Backup failed for Site library.test. Database or site_config.json may be corrupted
Traceback (most recent call last):
  File "/home/dell/frappe-bench/apps/frappe/frappe/commands/site.py", line 441, in backup
    force=True
  File "/home/dell/frappe-bench/apps/frappe/frappe/utils/backups.py", line 528, in scheduled_backup
    verbose=verbose,
  File "/home/dell/frappe-bench/apps/frappe/frappe/utils/backups.py", line 565, in new_backup
    compress_files=compress,
  File "/home/dell/frappe-bench/apps/frappe/frappe/utils/backups.py", line 85, in __init__
    self.setup_backup_tables()
  File "/home/dell/frappe-bench/apps/frappe/frappe/utils/backups.py", line 119, in setup_backup_tables
    existing_doctypes = set([x.name for x in frappe.get_all("DocType")])
  File "/home/dell/frappe-bench/apps/frappe/frappe/__init__.py", line 1460, in get_all
    return get_list(doctype, *args, **kwargs)
  File "/home/dell/frappe-bench/apps/frappe/frappe/__init__.py", line 1433, in get_list
    return frappe.model.db_query.DatabaseQuery(doctype).execute(*args, **kwargs)
  File "/home/dell/frappe-bench/apps/frappe/frappe/model/db_query.py", line 102, in execute
    self.columns = self.get_table_columns()
  File "/home/dell/frappe-bench/apps/frappe/frappe/model/db_query.py", line 339, in get_table_columns
    return get_table_columns(self.doctype)
  File "/home/dell/frappe-bench/apps/frappe/frappe/model/meta.py", line 49, in get_table_columns
    return frappe.db.get_table_columns(doctype)
  File "/home/dell/frappe-bench/apps/frappe/frappe/database/database.py", line 893, in get_table_columns
    columns = self.get_db_table_columns('tab' + doctype)
  File "/home/dell/frappe-bench/apps/frappe/frappe/database/database.py", line 884, in get_db_table_columns
    where table_name = %s ''', table)]
  File "/home/dell/frappe-bench/apps/frappe/frappe/database/database.py", line 122, in sql
    self.connect()
  File "/home/dell/frappe-bench/apps/frappe/frappe/database/database.py", line 74, in connect
    self._conn = self.get_connection()
  File "/home/dell/frappe-bench/apps/frappe/frappe/database/mariadb/database.py", line 82, in get_connection
    local_infile=frappe.conf.local_infile
  File "/home/dell/frappe-bench/env/lib/python3.6/site-packages/pymysql/connections.py", line 353, in __init__
    self.connect()
  File "/home/dell/frappe-bench/env/lib/python3.6/site-packages/pymysql/connections.py", line 633, in connect
    self._request_authentication()
  File "/home/dell/frappe-bench/env/lib/python3.6/site-packages/pymysql/connections.py", line 907, in _request_authentication
    auth_packet = self._read_packet()
  File "/home/dell/frappe-bench/env/lib/python3.6/site-packages/pymysql/connections.py", line 725, in _read_packet
    packet.raise_for_error()
  File "/home/dell/frappe-bench/env/lib/python3.6/site-packages/pymysql/protocol.py", line 221, in raise_for_error
    err.raise_mysql_exception(self._data)
  File "/home/dell/frappe-bench/env/lib/python3.6/site-packages/pymysql/err.py", line 143, in raise_mysql_exception
    raise errorclass(errno, errval)
pymysql.err.OperationalError: (1045, "Access denied for user '_ad03fa1a016ca1c4'@'localhost' (using password: YES)")

Backup failed for Site library.test1. Database or site_config.json may be corrupted
Traceback (most recent call last):
  File "/home/dell/frappe-bench/apps/frappe/frappe/commands/site.py", line 441, in backup
    force=True
  File "/home/dell/frappe-bench/apps/frappe/frappe/utils/backups.py", line 528, in scheduled_backup
    verbose=verbose,
  File "/home/dell/frappe-bench/apps/frappe/frappe/utils/backups.py", line 565, in new_backup
    compress_files=compress,
  File "/home/dell/frappe-bench/apps/frappe/frappe/utils/backups.py", line 85, in __init__
    self.setup_backup_tables()
  File "/home/dell/frappe-bench/apps/frappe/frappe/utils/backups.py", line 119, in setup_backup_tables
    existing_doctypes = set([x.name for x in frappe.get_all("DocType")])
  File "/home/dell/frappe-bench/apps/frappe/frappe/__init__.py", line 1460, in get_all
    return get_list(doctype, *args, **kwargs)
  File "/home/dell/frappe-bench/apps/frappe/frappe/__init__.py", line 1433, in get_list
    return frappe.model.db_query.DatabaseQuery(doctype).execute(*args, **kwargs)
  File "/home/dell/frappe-bench/apps/frappe/frappe/model/db_query.py", line 102, in execute
    self.columns = self.get_table_columns()
  File "/home/dell/frappe-bench/apps/frappe/frappe/model/db_query.py", line 339, in get_table_columns
    return get_table_columns(self.doctype)
  File "/home/dell/frappe-bench/apps/frappe/frappe/model/meta.py", line 49, in get_table_columns
    return frappe.db.get_table_columns(doctype)
  File "/home/dell/frappe-bench/apps/frappe/frappe/database/database.py", line 893, in get_table_columns
    columns = self.get_db_table_columns('tab' + doctype)
  File "/home/dell/frappe-bench/apps/frappe/frappe/database/database.py", line 884, in get_db_table_columns
    where table_name = %s ''', table)]
  File "/home/dell/frappe-bench/apps/frappe/frappe/database/database.py", line 122, in sql
    self.connect()
  File "/home/dell/frappe-bench/apps/frappe/frappe/database/database.py", line 74, in connect
    self._conn = self.get_connection()
  File "/home/dell/frappe-bench/apps/frappe/frappe/database/mariadb/database.py", line 82, in get_connection
    local_infile=frappe.conf.local_infile
  File "/home/dell/frappe-bench/env/lib/python3.6/site-packages/pymysql/connections.py", line 353, in __init__
    self.connect()
  File "/home/dell/frappe-bench/env/lib/python3.6/site-packages/pymysql/connections.py", line 633, in connect
    self._request_authentication()
  File "/home/dell/frappe-bench/env/lib/python3.6/site-packages/pymysql/connections.py", line 907, in _request_authentication
    auth_packet = self._read_packet()
  File "/home/dell/frappe-bench/env/lib/python3.6/site-packages/pymysql/connections.py", line 725, in _read_packet
    packet.raise_for_error()
  File "/home/dell/frappe-bench/env/lib/python3.6/site-packages/pymysql/protocol.py", line 221, in raise_for_error
    err.raise_mysql_exception(self._data)
  File "/home/dell/frappe-bench/env/lib/python3.6/site-packages/pymysql/err.py", line 143, in raise_mysql_exception
    raise errorclass(errno, errval)
pymysql.err.OperationalError: (1045, "Access denied for user '_ad03fa1a016ca1c4'@'localhost' (using password: YES)")

Backup failed for Site library.test2. Database or site_config.json may be corrupted
Traceback (most recent call last):
  File "/home/dell/frappe-bench/apps/frappe/frappe/commands/site.py", line 441, in backup
    force=True
  File "/home/dell/frappe-bench/apps/frappe/frappe/utils/backups.py", line 528, in scheduled_backup
    verbose=verbose,
  File "/home/dell/frappe-bench/apps/frappe/frappe/utils/backups.py", line 565, in new_backup
    compress_files=compress,
  File "/home/dell/frappe-bench/apps/frappe/frappe/utils/backups.py", line 85, in __init__
    self.setup_backup_tables()
  File "/home/dell/frappe-bench/apps/frappe/frappe/utils/backups.py", line 119, in setup_backup_tables
    existing_doctypes = set([x.name for x in frappe.get_all("DocType")])
  File "/home/dell/frappe-bench/apps/frappe/frappe/__init__.py", line 1460, in get_all
    return get_list(doctype, *args, **kwargs)
  File "/home/dell/frappe-bench/apps/frappe/frappe/__init__.py", line 1433, in get_list
    return frappe.model.db_query.DatabaseQuery(doctype).execute(*args, **kwargs)
  File "/home/dell/frappe-bench/apps/frappe/frappe/model/db_query.py", line 102, in execute
    self.columns = self.get_table_columns()
  File "/home/dell/frappe-bench/apps/frappe/frappe/model/db_query.py", line 339, in get_table_columns
    return get_table_columns(self.doctype)
  File "/home/dell/frappe-bench/apps/frappe/frappe/model/meta.py", line 49, in get_table_columns
    return frappe.db.get_table_columns(doctype)
  File "/home/dell/frappe-bench/apps/frappe/frappe/database/database.py", line 893, in get_table_columns
    columns = self.get_db_table_columns('tab' + doctype)
  File "/home/dell/frappe-bench/apps/frappe/frappe/database/database.py", line 884, in get_db_table_columns
    where table_name = %s ''', table)]
  File "/home/dell/frappe-bench/apps/frappe/frappe/database/database.py", line 122, in sql
    self.connect()
  File "/home/dell/frappe-bench/apps/frappe/frappe/database/database.py", line 74, in connect
    self._conn = self.get_connection()
  File "/home/dell/frappe-bench/apps/frappe/frappe/database/mariadb/database.py", line 82, in get_connection
    local_infile=frappe.conf.local_infile
  File "/home/dell/frappe-bench/env/lib/python3.6/site-packages/pymysql/connections.py", line 353, in __init__
    self.connect()
  File "/home/dell/frappe-bench/env/lib/python3.6/site-packages/pymysql/connections.py", line 633, in connect
    self._request_authentication()
  File "/home/dell/frappe-bench/env/lib/python3.6/site-packages/pymysql/connections.py", line 907, in _request_authentication
    auth_packet = self._read_packet()
  File "/home/dell/frappe-bench/env/lib/python3.6/site-packages/pymysql/connections.py", line 725, in _read_packet
    packet.raise_for_error()
  File "/home/dell/frappe-bench/env/lib/python3.6/site-packages/pymysql/protocol.py", line 221, in raise_for_error
    err.raise_mysql_exception(self._data)
  File "/home/dell/frappe-bench/env/lib/python3.6/site-packages/pymysql/err.py", line 143, in raise_mysql_exception
    raise errorclass(errno, errval)
pymysql.err.OperationalError: (1045, "Access denied for user '_ad03fa1a016ca1c4'@'localhost' (using password: YES)")

Backup failed for Site library.test. Database or site_config.json may be corrupted
Traceback (most recent call last):
  File "/home/dell/frappe-bench/apps/frappe/frappe/commands/site.py", line 441, in backup
    force=True
  File "/home/dell/frappe-bench/apps/frappe/frappe/utils/backups.py", line 528, in scheduled_backup
    verbose=verbose,
  File "/home/dell/frappe-bench/apps/frappe/frappe/utils/backups.py", line 565, in new_backup
    compress_files=compress,
  File "/home/dell/frappe-bench/apps/frappe/frappe/utils/backups.py", line 85, in __init__
    self.setup_backup_tables()
  File "/home/dell/frappe-bench/apps/frappe/frappe/utils/backups.py", line 119, in setup_backup_tables
    existing_doctypes = set([x.name for x in frappe.get_all("DocType")])
  File "/home/dell/frappe-bench/apps/frappe/frappe/__init__.py", line 1460, in get_all
    return get_list(doctype, *args, **kwargs)
  File "/home/dell/frappe-bench/apps/frappe/frappe/__init__.py", line 1433, in get_list
    return frappe.model.db_query.DatabaseQuery(doctype).execute(*args, **kwargs)
  File "/home/dell/frappe-bench/apps/frappe/frappe/model/db_query.py", line 102, in execute
    self.columns = self.get_table_columns()
  File "/home/dell/frappe-bench/apps/frappe/frappe/model/db_query.py", line 339, in get_table_columns
    return get_table_columns(self.doctype)
  File "/home/dell/frappe-bench/apps/frappe/frappe/model/meta.py", line 49, in get_table_columns
    return frappe.db.get_table_columns(doctype)
  File "/home/dell/frappe-bench/apps/frappe/frappe/database/database.py", line 893, in get_table_columns
    columns = self.get_db_table_columns('tab' + doctype)
  File "/home/dell/frappe-bench/apps/frappe/frappe/database/database.py", line 884, in get_db_table_columns
    where table_name = %s ''', table)]
  File "/home/dell/frappe-bench/apps/frappe/frappe/database/database.py", line 122, in sql
    self.connect()
  File "/home/dell/frappe-bench/apps/frappe/frappe/database/database.py", line 74, in connect
    self._conn = self.get_connection()
  File "/home/dell/frappe-bench/apps/frappe/frappe/database/mariadb/database.py", line 82, in get_connection
    local_infile=frappe.conf.local_infile
  File "/home/dell/frappe-bench/env/lib/python3.6/site-packages/pymysql/connections.py", line 353, in __init__
    self.connect()
  File "/home/dell/frappe-bench/env/lib/python3.6/site-packages/pymysql/connections.py", line 633, in connect
    self._request_authentication()
  File "/home/dell/frappe-bench/env/lib/python3.6/site-packages/pymysql/connections.py", line 907, in _request_authentication
    auth_packet = self._read_packet()
  File "/home/dell/frappe-bench/env/lib/python3.6/site-packages/pymysql/connections.py", line 725, in _read_packet
    packet.raise_for_error()
  File "/home/dell/frappe-bench/env/lib/python3.6/site-packages/pymysql/protocol.py", line 221, in raise_for_error
    err.raise_mysql_exception(self._data)
  File "/home/dell/frappe-bench/env/lib/python3.6/site-packages/pymysql/err.py", line 143, in raise_mysql_exception
    raise errorclass(errno, errval)
pymysql.err.OperationalError: (1045, "Access denied for user '_ad03fa1a016ca1c4'@'localhost' (using password: YES)")

Backup failed for Site library.test1. Database or site_config.json may be corrupted
Traceback (most recent call last):
  File "/home/dell/frappe-bench/apps/frappe/frappe/commands/site.py", line 441, in backup
    force=True
  File "/home/dell/frappe-bench/apps/frappe/frappe/utils/backups.py", line 528, in scheduled_backup
    verbose=verbose,
  File "/home/dell/frappe-bench/apps/frappe/frappe/utils/backups.py", line 565, in new_backup
    compress_files=compress,
  File "/home/dell/frappe-bench/apps/frappe/frappe/utils/backups.py", line 85, in __init__
    self.setup_backup_tables()
  File "/home/dell/frappe-bench/apps/frappe/frappe/utils/backups.py", line 119, in setup_backup_tables
    existing_doctypes = set([x.name for x in frappe.get_all("DocType")])
  File "/home/dell/frappe-bench/apps/frappe/frappe/__init__.py", line 1460, in get_all
    return get_list(doctype, *args, **kwargs)
  File "/home/dell/frappe-bench/apps/frappe/frappe/__init__.py", line 1433, in get_list
    return frappe.model.db_query.DatabaseQuery(doctype).execute(*args, **kwargs)
  File "/home/dell/frappe-bench/apps/frappe/frappe/model/db_query.py", line 102, in execute
    self.columns = self.get_table_columns()
  File "/home/dell/frappe-bench/apps/frappe/frappe/model/db_query.py", line 339, in get_table_columns
    return get_table_columns(self.doctype)
  File "/home/dell/frappe-bench/apps/frappe/frappe/model/meta.py", line 49, in get_table_columns
    return frappe.db.get_table_columns(doctype)
  File "/home/dell/frappe-bench/apps/frappe/frappe/database/database.py", line 893, in get_table_columns
    columns = self.get_db_table_columns('tab' + doctype)
  File "/home/dell/frappe-bench/apps/frappe/frappe/database/database.py", line 884, in get_db_table_columns
    where table_name = %s ''', table)]
  File "/home/dell/frappe-bench/apps/frappe/frappe/database/database.py", line 122, in sql
    self.connect()
  File "/home/dell/frappe-bench/apps/frappe/frappe/database/database.py", line 74, in connect
    self._conn = self.get_connection()
  File "/home/dell/frappe-bench/apps/frappe/frappe/database/mariadb/database.py", line 82, in get_connection
    local_infile=frappe.conf.local_infile
  File "/home/dell/frappe-bench/env/lib/python3.6/site-packages/pymysql/connections.py", line 353, in __init__
    self.connect()
  File "/home/dell/frappe-bench/env/lib/python3.6/site-packages/pymysql/connections.py", line 633, in connect
    self._request_authentication()
  File "/home/dell/frappe-bench/env/lib/python3.6/site-packages/pymysql/connections.py", line 907, in _request_authentication
    auth_packet = self._read_packet()
  File "/home/dell/frappe-bench/env/lib/python3.6/site-packages/pymysql/connections.py", line 725, in _read_packet
    packet.raise_for_error()
  File "/home/dell/frappe-bench/env/lib/python3.6/site-packages/pymysql/protocol.py", line 221, in raise_for_error
    err.raise_mysql_exception(self._data)
  File "/home/dell/frappe-bench/env/lib/python3.6/site-packages/pymysql/err.py", line 143, in raise_mysql_exception
    raise errorclass(errno, errval)
pymysql.err.OperationalError: (1045, "Access denied for user '_ad03fa1a016ca1c4'@'localhost' (using password: YES)")

Backup failed for Site library.test2. Database or site_config.json may be corrupted
Traceback (most recent call last):
  File "/home/dell/frappe-bench/apps/frappe/frappe/commands/site.py", line 441, in backup
    force=True
  File "/home/dell/frappe-bench/apps/frappe/frappe/utils/backups.py", line 528, in scheduled_backup
    verbose=verbose,
  File "/home/dell/frappe-bench/apps/frappe/frappe/utils/backups.py", line 565, in new_backup
    compress_files=compress,
  File "/home/dell/frappe-bench/apps/frappe/frappe/utils/backups.py", line 85, in __init__
    self.setup_backup_tables()
  File "/home/dell/frappe-bench/apps/frappe/frappe/utils/backups.py", line 119, in setup_backup_tables
    existing_doctypes = set([x.name for x in frappe.get_all("DocType")])
  File "/home/dell/frappe-bench/apps/frappe/frappe/__init__.py", line 1460, in get_all
    return get_list(doctype, *args, **kwargs)
  File "/home/dell/frappe-bench/apps/frappe/frappe/__init__.py", line 1433, in get_list
    return frappe.model.db_query.DatabaseQuery(doctype).execute(*args, **kwargs)
  File "/home/dell/frappe-bench/apps/frappe/frappe/model/db_query.py", line 102, in execute
    self.columns = self.get_table_columns()
  File "/home/dell/frappe-bench/apps/frappe/frappe/model/db_query.py", line 339, in get_table_columns
    return get_table_columns(self.doctype)
  File "/home/dell/frappe-bench/apps/frappe/frappe/model/meta.py", line 49, in get_table_columns
    return frappe.db.get_table_columns(doctype)
  File "/home/dell/frappe-bench/apps/frappe/frappe/database/database.py", line 893, in get_table_columns
    columns = self.get_db_table_columns('tab' + doctype)
  File "/home/dell/frappe-bench/apps/frappe/frappe/database/database.py", line 884, in get_db_table_columns
    where table_name = %s ''', table)]
  File "/home/dell/frappe-bench/apps/frappe/frappe/database/database.py", line 122, in sql
    self.connect()
  File "/home/dell/frappe-bench/apps/frappe/frappe/database/database.py", line 74, in connect
    self._conn = self.get_connection()
  File "/home/dell/frappe-bench/apps/frappe/frappe/database/mariadb/database.py", line 82, in get_connection
    local_infile=frappe.conf.local_infile
  File "/home/dell/frappe-bench/env/lib/python3.6/site-packages/pymysql/connections.py", line 353, in __init__
    self.connect()
  File "/home/dell/frappe-bench/env/lib/python3.6/site-packages/pymysql/connections.py", line 633, in connect
    self._request_authentication()
  File "/home/dell/frappe-bench/env/lib/python3.6/site-packages/pymysql/connections.py", line 907, in _request_authentication
    auth_packet = self._read_packet()
  File "/home/dell/frappe-bench/env/lib/python3.6/site-packages/pymysql/connections.py", line 725, in _read_packet
    packet.raise_for_error()
  File "/home/dell/frappe-bench/env/lib/python3.6/site-packages/pymysql/protocol.py", line 221, in raise_for_error
    err.raise_mysql_exception(self._data)
  File "/home/dell/frappe-bench/env/lib/python3.6/site-packages/pymysql/err.py", line 143, in raise_mysql_exception
    raise errorclass(errno, errval)
pymysql.err.OperationalError: (1045, "Access denied for user '_ad03fa1a016ca1c4'@'localhost' (using password: YES)")

